[0m18:38:48.958939 [debug] [MainThread]: Sending event: {'category': 'dbt', 'action': 'invocation', 'label': 'start', 'context': [<snowplow_tracker.self_describing_json.SelfDescribingJson object at 0x000001D8C363B150>, <snowplow_tracker.self_describing_json.SelfDescribingJson object at 0x000001D8C3640690>, <snowplow_tracker.self_describing_json.SelfDescribingJson object at 0x000001D8C3640F90>]}


============================== 18:38:48.971405 | 04b6df53-fb6d-4dc1-a47a-600fb8fa7d0e ==============================
[0m18:38:48.971405 [info ] [MainThread]: Running with dbt=1.10.13
[0m18:38:48.974391 [debug] [MainThread]: running dbt with arguments {'printer_width': '80', 'write_json': 'True', 'cache_selected_only': 'False', 'warn_error': 'None', 'empty': 'None', 'debug': 'False', 'static_parser': 'True', 'log_cache_events': 'False', 'profiles_dir': 'C:\\Users\\LARRY\\.dbt', 'log_format': 'default', 'quiet': 'False', 'use_colors': 'True', 'partial_parse': 'True', 'version_check': 'True', 'log_path': 'logs', 'introspect': 'True', 'invocation_command': 'dbt init dbt-data-analysis', 'fail_fast': 'False', 'warn_error_options': 'WarnErrorOptionsV2(error=[], warn=[], silence=[])', 'no_print': 'None', 'send_anonymous_usage_stats': 'True', 'indirect_selection': 'eager', 'use_experimental_parser': 'False', 'target_path': 'None'}
[0m18:38:49.127690 [info ] [MainThread]: Creating dbt configuration folder at C:\Users\LARRY\.dbt
[0m18:51:52.498548 [debug] [MainThread]: Starter project path: C:\Users\LARRY\anaconda3\envs\tech-interview\Lib\site-packages\dbt\include\starter_project
[0m18:51:52.619770 [info ] [MainThread]: 
Your new dbt project "dbt_data_analysis" was created!

For more information on how to configure the profiles.yml file,
please consult the dbt documentation here:

  https://docs.getdbt.com/docs/configure-your-profile

One more thing:

Need help? Don't hesitate to reach out to us via GitHub issues or on Slack:

  https://community.getdbt.com/

Happy modeling!

[0m18:51:52.628645 [info ] [MainThread]: Setting up your profile.
[0m18:53:08.902245 [info ] [MainThread]: Profile dbt_data_analysis written to C:\Users\LARRY\.dbt\profiles.yml using target's sample configuration. Once updated, you'll be able to start developing with dbt.
[0m18:53:08.905294 [debug] [MainThread]: Command `dbt init` succeeded at 18:53:08.903760 after 860.30 seconds
[0m18:53:08.906837 [debug] [MainThread]: Sending event: {'category': 'dbt', 'action': 'invocation', 'label': 'end', 'context': [<snowplow_tracker.self_describing_json.SelfDescribingJson object at 0x000001D8C35D7F10>, <snowplow_tracker.self_describing_json.SelfDescribingJson object at 0x000001D8C2740290>, <snowplow_tracker.self_describing_json.SelfDescribingJson object at 0x000001D8C336F450>]}
[0m18:53:08.908346 [debug] [MainThread]: Flushing usage events
[0m18:53:11.130490 [debug] [MainThread]: An error was encountered while trying to flush usage events
[0m14:34:38.229024 [debug] [MainThread]: Sending event: {'category': 'dbt', 'action': 'invocation', 'label': 'start', 'context': [<snowplow_tracker.self_describing_json.SelfDescribingJson object at 0x0000021D078E2990>, <snowplow_tracker.self_describing_json.SelfDescribingJson object at 0x0000021D0AF3BED0>, <snowplow_tracker.self_describing_json.SelfDescribingJson object at 0x0000021D0B2BF410>]}


============================== 14:34:38.254499 | b0be8a88-7199-4412-bf88-59be91e6cd2c ==============================
[0m14:34:38.254499 [info ] [MainThread]: Running with dbt=1.10.13
[0m14:34:38.254499 [debug] [MainThread]: running dbt with arguments {'printer_width': '80', 'target_path': 'None', 'cache_selected_only': 'False', 'warn_error': 'None', 'profiles_dir': 'C:\\Users\\LARRY\\.dbt', 'debug': 'False', 'static_parser': 'True', 'log_cache_events': 'False', 'empty': 'None', 'quiet': 'False', 'log_format': 'default', 'use_colors': 'True', 'partial_parse': 'True', 'version_check': 'True', 'log_path': 'logs', 'introspect': 'True', 'invocation_command': 'dbt seed', 'fail_fast': 'False', 'no_print': 'None', 'warn_error_options': 'WarnErrorOptionsV2(error=[], warn=[], silence=[])', 'send_anonymous_usage_stats': 'True', 'indirect_selection': 'eager', 'use_experimental_parser': 'False', 'write_json': 'True'}
[0m14:34:38.259387 [error] [MainThread]: Encountered an error:
Runtime Error
  No dbt_project.yml found at expected path C:\Users\LARRY\Documents\Scripts\data-engineering-path\dbt-data-analysis\dbt_project.yml
  Verify that each entry within packages.yml (and their transitive dependencies) contains a file named dbt_project.yml
  
[0m14:34:38.261455 [debug] [MainThread]: Command `dbt seed` failed at 14:34:38.261455 after 0.19 seconds
[0m14:34:38.261455 [debug] [MainThread]: Sending event: {'category': 'dbt', 'action': 'invocation', 'label': 'end', 'context': [<snowplow_tracker.self_describing_json.SelfDescribingJson object at 0x0000021D04472D90>, <snowplow_tracker.self_describing_json.SelfDescribingJson object at 0x0000021D0B2EF290>, <snowplow_tracker.self_describing_json.SelfDescribingJson object at 0x0000021D043E1610>]}
[0m14:34:38.261455 [debug] [MainThread]: Flushing usage events
[0m14:34:40.839999 [debug] [MainThread]: An error was encountered while trying to flush usage events
[0m19:33:38.556503 [debug] [MainThread]: Sending event: {'category': 'dbt', 'action': 'invocation', 'label': 'start', 'context': [<snowplow_tracker.self_describing_json.SelfDescribingJson object at 0x000001DC9C3379D0>, <snowplow_tracker.self_describing_json.SelfDescribingJson object at 0x000001DC9C38ED50>, <snowplow_tracker.self_describing_json.SelfDescribingJson object at 0x000001DC9C3556D0>]}


============================== 19:33:38.572258 | 4dcb7d32-2b65-43b5-a534-6e690e468537 ==============================
[0m19:33:38.572258 [info ] [MainThread]: Running with dbt=1.10.13
[0m19:33:38.578326 [debug] [MainThread]: running dbt with arguments {'printer_width': '80', 'write_json': 'True', 'cache_selected_only': 'False', 'warn_error': 'None', 'profiles_dir': 'C:\\Users\\LARRY\\.dbt', 'debug': 'False', 'static_parser': 'True', 'log_cache_events': 'False', 'empty': 'None', 'quiet': 'False', 'log_format': 'default', 'use_colors': 'True', 'partial_parse': 'True', 'version_check': 'True', 'log_path': 'logs', 'introspect': 'True', 'invocation_command': 'dbt init', 'fail_fast': 'False', 'warn_error_options': 'WarnErrorOptionsV2(error=[], warn=[], silence=[])', 'no_print': 'None', 'send_anonymous_usage_stats': 'True', 'indirect_selection': 'eager', 'target_path': 'None', 'use_experimental_parser': 'False'}
[0m19:33:48.622914 [debug] [MainThread]: Starter project path: C:\Users\LARRY\anaconda3\envs\tech-interview\Lib\site-packages\dbt\include\starter_project
[0m19:33:48.701710 [info ] [MainThread]: 
Your new dbt project "forums_analyses" was created!

For more information on how to configure the profiles.yml file,
please consult the dbt documentation here:

  https://docs.getdbt.com/docs/configure-your-profile

One more thing:

Need help? Don't hesitate to reach out to us via GitHub issues or on Slack:

  https://community.getdbt.com/

Happy modeling!

[0m19:33:48.710252 [info ] [MainThread]: Setting up your profile.
[0m20:01:21.609266 [info ] [MainThread]: Profile forums_analyses written to C:\Users\LARRY\.dbt\profiles.yml using target's profile_template.yml and your supplied values. Run 'dbt debug' to validate the connection.
[0m20:01:21.617728 [debug] [MainThread]: Command `dbt init` succeeded at 20:01:21.617728 after 1663.24 seconds
[0m20:01:21.619279 [debug] [MainThread]: Sending event: {'category': 'dbt', 'action': 'invocation', 'label': 'end', 'context': [<snowplow_tracker.self_describing_json.SelfDescribingJson object at 0x000001DC95197450>, <snowplow_tracker.self_describing_json.SelfDescribingJson object at 0x000001DC9C357650>, <snowplow_tracker.self_describing_json.SelfDescribingJson object at 0x000001DC9C357C10>]}
[0m20:01:21.621299 [debug] [MainThread]: Flushing usage events
[0m20:01:23.925053 [debug] [MainThread]: An error was encountered while trying to flush usage events
[0m20:03:05.600313 [debug] [MainThread]: Sending event: {'category': 'dbt', 'action': 'invocation', 'label': 'start', 'context': [<snowplow_tracker.self_describing_json.SelfDescribingJson object at 0x000001B6D3AC2E10>, <snowplow_tracker.self_describing_json.SelfDescribingJson object at 0x000001B6D74D7050>, <snowplow_tracker.self_describing_json.SelfDescribingJson object at 0x000001B6D74D6AD0>]}


============================== 20:03:05.605688 | d021da02-4eea-4b70-9b9f-c4e5aab2f2de ==============================
[0m20:03:05.605688 [info ] [MainThread]: Running with dbt=1.10.13
[0m20:03:05.605688 [debug] [MainThread]: running dbt with arguments {'printer_width': '80', 'use_experimental_parser': 'False', 'cache_selected_only': 'False', 'warn_error': 'None', 'profiles_dir': 'C:\\Users\\LARRY\\.dbt', 'debug': 'False', 'static_parser': 'True', 'log_cache_events': 'False', 'empty': 'None', 'quiet': 'False', 'log_format': 'default', 'use_colors': 'True', 'partial_parse': 'True', 'version_check': 'True', 'log_path': 'logs', 'introspect': 'True', 'warn_error_options': 'WarnErrorOptionsV2(error=[], warn=[], silence=[])', 'fail_fast': 'False', 'invocation_command': 'dbt debug', 'no_print': 'None', 'send_anonymous_usage_stats': 'True', 'indirect_selection': 'eager', 'target_path': 'None', 'write_json': 'True'}
[0m20:03:05.649814 [info ] [MainThread]: dbt version: 1.10.13
[0m20:03:05.651828 [info ] [MainThread]: python version: 3.11.8
[0m20:03:05.651828 [info ] [MainThread]: python path: C:\Users\LARRY\anaconda3\envs\tech-interview\python.exe
[0m20:03:05.651828 [info ] [MainThread]: os info: Windows-10-10.0.26100-SP0
[0m20:03:07.150202 [info ] [MainThread]: Using profiles dir at C:\Users\LARRY\.dbt
[0m20:03:07.166512 [info ] [MainThread]: Using profiles.yml file at C:\Users\LARRY\.dbt\profiles.yml
[0m20:03:07.168807 [info ] [MainThread]: Using dbt_project.yml file at C:\Users\LARRY\Documents\Scripts\data-engineering-path\subreddit-analyses\dags\dbt_project.yml
[0m20:03:07.169738 [info ] [MainThread]: adapter type: snowflake
[0m20:03:07.169738 [info ] [MainThread]: adapter version: 1.10.2
[0m20:03:07.169738 [info ] [MainThread]: Configuration:
[0m20:03:07.169738 [info ] [MainThread]:   profiles.yml file [[32mOK found and valid[0m]
[0m20:03:07.169738 [info ] [MainThread]:   dbt_project.yml file [[31mERROR not found[0m]
[0m20:03:07.169738 [info ] [MainThread]: Required dependencies:
[0m20:03:07.169738 [debug] [MainThread]: Executing "git --help"
[0m20:03:07.230869 [debug] [MainThread]: STDOUT: "b"usage: git [-v | --version] [-h | --help] [-C <path>] [-c <name>=<value>]\n           [--exec-path[=<path>]] [--html-path] [--man-path] [--info-path]\n           [-p | --paginate | -P | --no-pager] [--no-replace-objects] [--no-lazy-fetch]\n           [--no-optional-locks] [--no-advice] [--bare] [--git-dir=<path>]\n           [--work-tree=<path>] [--namespace=<name>] [--config-env=<name>=<envvar>]\n           <command> [<args>]\n\nThese are common Git commands used in various situations:\n\nstart a working area (see also: git help tutorial)\n   clone     Clone a repository into a new directory\n   init      Create an empty Git repository or reinitialize an existing one\n\nwork on the current change (see also: git help everyday)\n   add       Add file contents to the index\n   mv        Move or rename a file, a directory, or a symlink\n   restore   Restore working tree files\n   rm        Remove files from the working tree and from the index\n\nexamine the history and state (see also: git help revisions)\n   bisect    Use binary search to find the commit that introduced a bug\n   diff      Show changes between commits, commit and working tree, etc\n   grep      Print lines matching a pattern\n   log       Show commit logs\n   show      Show various types of objects\n   status    Show the working tree status\n\ngrow, mark and tweak your common history\n   branch    List, create, or delete branches\n   commit    Record changes to the repository\n   merge     Join two or more development histories together\n   rebase    Reapply commits on top of another base tip\n   reset     Reset current HEAD to the specified state\n   switch    Switch branches\n   tag       Create, list, delete or verify a tag object signed with GPG\n\ncollaborate (see also: git help workflows)\n   fetch     Download objects and refs from another repository\n   pull      Fetch from and integrate with another repository or a local branch\n   push      Update remote refs along with associated objects\n\n'git help -a' and 'git help -g' list available subcommands and some\nconcept guides. See 'git help <command>' or 'git help <concept>'\nto read about a specific subcommand or concept.\nSee 'git help git' for an overview of the system.\n""
[0m20:03:07.230869 [debug] [MainThread]: STDERR: "b''"
[0m20:03:07.236964 [info ] [MainThread]:  - git [[32mOK found[0m]

[0m20:03:07.236964 [info ] [MainThread]: Connection:
[0m20:03:07.236964 [info ] [MainThread]:   account: https://JBISURP-LN34944.snowflakecomputing.com
[0m20:03:07.239158 [info ] [MainThread]:   user: AKUSLAYER3000
[0m20:03:07.239158 [info ] [MainThread]:   database: subreddit_analyses_db
[0m20:03:07.239158 [info ] [MainThread]:   warehouse: COMPUTE_WH
[0m20:03:07.239158 [info ] [MainThread]:   role: ACCOUNTADMIN
[0m20:03:07.239158 [info ] [MainThread]:   schema: subreddit_analyses_bronze
[0m20:03:07.242458 [info ] [MainThread]:   authenticator: None
[0m20:03:07.242458 [info ] [MainThread]:   oauth_client_id: None
[0m20:03:07.243873 [info ] [MainThread]:   query_tag: None
[0m20:03:07.245382 [info ] [MainThread]:   client_session_keep_alive: False
[0m20:03:07.247152 [info ] [MainThread]:   host: None
[0m20:03:07.247914 [info ] [MainThread]:   port: None
[0m20:03:07.248656 [info ] [MainThread]:   proxy_host: None
[0m20:03:07.248656 [info ] [MainThread]:   proxy_port: None
[0m20:03:07.249945 [info ] [MainThread]:   protocol: None
[0m20:03:07.249945 [info ] [MainThread]:   connect_retries: 1
[0m20:03:07.249945 [info ] [MainThread]:   connect_timeout: None
[0m20:03:07.252750 [info ] [MainThread]:   retry_on_database_errors: False
[0m20:03:07.252750 [info ] [MainThread]:   retry_all: False
[0m20:03:07.253607 [info ] [MainThread]:   insecure_mode: False
[0m20:03:07.253607 [info ] [MainThread]:   reuse_connections: True
[0m20:03:07.253607 [info ] [MainThread]:   s3_stage_vpce_dns_name: None
[0m20:03:07.253607 [info ] [MainThread]: Registered adapter: snowflake=1.10.2
[0m20:03:07.699955 [debug] [MainThread]: Acquiring new snowflake connection 'debug'
[0m20:03:08.146409 [debug] [MainThread]: Using snowflake connection "debug"
[0m20:03:08.146409 [debug] [MainThread]: On debug: select 1 as id
[0m20:03:08.146409 [debug] [MainThread]: Opening a new connection, currently in state init
[0m20:03:39.972346 [error] [MainThread]: Encountered an error:

[0m20:03:40.004253 [error] [MainThread]: Traceback (most recent call last):
  File "C:\Users\LARRY\anaconda3\envs\tech-interview\Lib\site-packages\snowflake\connector\vendored\urllib3\connection.py", line 198, in _new_conn
    sock = connection.create_connection(
           ^^^^^^^^^^^^^^^^^^^^^^^^^^^^^
  File "C:\Users\LARRY\anaconda3\envs\tech-interview\Lib\site-packages\snowflake\connector\vendored\urllib3\util\connection.py", line 60, in create_connection
    for res in socket.getaddrinfo(host, port, family, socket.SOCK_STREAM):
               ^^^^^^^^^^^^^^^^^^^^^^^^^^^^^^^^^^^^^^^^^^^^^^^^^^^^^^^^^^
  File "C:\Users\LARRY\anaconda3\envs\tech-interview\Lib\socket.py", line 962, in getaddrinfo
    for res in _socket.getaddrinfo(host, port, family, type, proto, flags):
               ^^^^^^^^^^^^^^^^^^^^^^^^^^^^^^^^^^^^^^^^^^^^^^^^^^^^^^^^^^^
socket.gaierror: [Errno 11001] getaddrinfo failed

The above exception was the direct cause of the following exception:

Traceback (most recent call last):
  File "C:\Users\LARRY\anaconda3\envs\tech-interview\Lib\site-packages\snowflake\connector\vendored\urllib3\connectionpool.py", line 787, in urlopen
    response = self._make_request(
               ^^^^^^^^^^^^^^^^^^^
  File "C:\Users\LARRY\anaconda3\envs\tech-interview\Lib\site-packages\snowflake\connector\vendored\urllib3\connectionpool.py", line 488, in _make_request
    raise new_e
  File "C:\Users\LARRY\anaconda3\envs\tech-interview\Lib\site-packages\snowflake\connector\vendored\urllib3\connectionpool.py", line 464, in _make_request
    self._validate_conn(conn)
  File "C:\Users\LARRY\anaconda3\envs\tech-interview\Lib\site-packages\snowflake\connector\vendored\urllib3\connectionpool.py", line 1093, in _validate_conn
    conn.connect()
  File "C:\Users\LARRY\anaconda3\envs\tech-interview\Lib\site-packages\snowflake\connector\vendored\urllib3\connection.py", line 762, in connect
    self.sock = sock = self._new_conn()
                       ^^^^^^^^^^^^^^^^
  File "C:\Users\LARRY\anaconda3\envs\tech-interview\Lib\site-packages\snowflake\connector\vendored\urllib3\connection.py", line 205, in _new_conn
    raise NameResolutionError(self.host, self, e) from e
snowflake.connector.vendored.urllib3.exceptions.NameResolutionError: <snowflake.connector.vendored.urllib3.connection.HTTPSConnection object at 0x000001B6F1B94610>: Failed to resolve 'https' ([Errno 11001] getaddrinfo failed)

The above exception was the direct cause of the following exception:

Traceback (most recent call last):
  File "C:\Users\LARRY\anaconda3\envs\tech-interview\Lib\site-packages\snowflake\connector\vendored\requests\adapters.py", line 644, in send
    resp = conn.urlopen(
           ^^^^^^^^^^^^^
  File "C:\Users\LARRY\anaconda3\envs\tech-interview\Lib\site-packages\snowflake\connector\vendored\urllib3\connectionpool.py", line 871, in urlopen
    return self.urlopen(
           ^^^^^^^^^^^^^
  File "C:\Users\LARRY\anaconda3\envs\tech-interview\Lib\site-packages\snowflake\connector\vendored\urllib3\connectionpool.py", line 841, in urlopen
    retries = retries.increment(
              ^^^^^^^^^^^^^^^^^^
  File "C:\Users\LARRY\anaconda3\envs\tech-interview\Lib\site-packages\snowflake\connector\vendored\urllib3\util\retry.py", line 519, in increment
    raise MaxRetryError(_pool, url, reason) from reason  # type: ignore[arg-type]
    ^^^^^^^^^^^^^^^^^^^^^^^^^^^^^^^^^^^^^^^^^^^^^^^^^^^
snowflake.connector.vendored.urllib3.exceptions.MaxRetryError: HTTPSConnectionPool(host='https', port=443): Max retries exceeded with url: /JBISURP-LN34944.snowflakecomputing.com.snowflakecomputing.com:443/session/v1/login-request?request_id=58c13531-7f29-426a-a7b2-737b1518a2e6&databaseName=subreddit_analyses_db&schemaName=subreddit_analyses_bronze&warehouse=COMPUTE_WH&roleName=ACCOUNTADMIN (Caused by NameResolutionError("<snowflake.connector.vendored.urllib3.connection.HTTPSConnection object at 0x000001B6F1B94610>: Failed to resolve 'https' ([Errno 11001] getaddrinfo failed)"))

During handling of the above exception, another exception occurred:

Traceback (most recent call last):
  File "C:\Users\LARRY\anaconda3\envs\tech-interview\Lib\site-packages\snowflake\connector\network.py", line 1083, in _request_exec
    raw_ret = session.request(
              ^^^^^^^^^^^^^^^^
  File "C:\Users\LARRY\anaconda3\envs\tech-interview\Lib\site-packages\snowflake\connector\vendored\requests\sessions.py", line 589, in request
    resp = self.send(prep, **send_kwargs)
           ^^^^^^^^^^^^^^^^^^^^^^^^^^^^^^
  File "C:\Users\LARRY\anaconda3\envs\tech-interview\Lib\site-packages\snowflake\connector\vendored\requests\sessions.py", line 703, in send
    r = adapter.send(request, **kwargs)
        ^^^^^^^^^^^^^^^^^^^^^^^^^^^^^^^
  File "C:\Users\LARRY\anaconda3\envs\tech-interview\Lib\site-packages\snowflake\connector\vendored\requests\adapters.py", line 677, in send
    raise ConnectionError(e, request=request)
snowflake.connector.vendored.requests.exceptions.ConnectionError: HTTPSConnectionPool(host='https', port=443): Max retries exceeded with url: /JBISURP-LN34944.snowflakecomputing.com.snowflakecomputing.com:443/session/v1/login-request?request_id=58c13531-7f29-426a-a7b2-737b1518a2e6&databaseName=subreddit_analyses_db&schemaName=subreddit_analyses_bronze&warehouse=COMPUTE_WH&roleName=ACCOUNTADMIN (Caused by NameResolutionError("<snowflake.connector.vendored.urllib3.connection.HTTPSConnection object at 0x000001B6F1B94610>: Failed to resolve 'https' ([Errno 11001] getaddrinfo failed)"))

During handling of the above exception, another exception occurred:

Traceback (most recent call last):
  File "C:\Users\LARRY\anaconda3\envs\tech-interview\Lib\site-packages\snowflake\connector\connection.py", line 1736, in _authenticate
    auth.authenticate(
  File "C:\Users\LARRY\anaconda3\envs\tech-interview\Lib\site-packages\snowflake\connector\auth\_auth.py", line 238, in authenticate
    ret = self._rest._post_request(
          ^^^^^^^^^^^^^^^^^^^^^^^^^
  File "C:\Users\LARRY\anaconda3\envs\tech-interview\Lib\site-packages\snowflake\connector\network.py", line 728, in _post_request
    ret = self.fetch(
          ^^^^^^^^^^^
  File "C:\Users\LARRY\anaconda3\envs\tech-interview\Lib\site-packages\snowflake\connector\network.py", line 847, in fetch
    ret = self._request_exec_wrapper(
          ^^^^^^^^^^^^^^^^^^^^^^^^^^^
  File "C:\Users\LARRY\anaconda3\envs\tech-interview\Lib\site-packages\snowflake\connector\network.py", line 988, in _request_exec_wrapper
    raise e
  File "C:\Users\LARRY\anaconda3\envs\tech-interview\Lib\site-packages\snowflake\connector\network.py", line 898, in _request_exec_wrapper
    return_object = self._request_exec(
                    ^^^^^^^^^^^^^^^^^^^
  File "C:\Users\LARRY\anaconda3\envs\tech-interview\Lib\site-packages\snowflake\connector\network.py", line 1181, in _request_exec
    raise OperationalError(
snowflake.connector.errors.OperationalError: 251011: ConnectionTimeout occurred during login. Will be handled by authenticator

During handling of the above exception, another exception occurred:

Traceback (most recent call last):
  File "C:\Users\LARRY\anaconda3\envs\tech-interview\Lib\site-packages\snowflake\connector\vendored\urllib3\connection.py", line 198, in _new_conn
    sock = connection.create_connection(
           ^^^^^^^^^^^^^^^^^^^^^^^^^^^^^
  File "C:\Users\LARRY\anaconda3\envs\tech-interview\Lib\site-packages\snowflake\connector\vendored\urllib3\util\connection.py", line 60, in create_connection
    for res in socket.getaddrinfo(host, port, family, socket.SOCK_STREAM):
               ^^^^^^^^^^^^^^^^^^^^^^^^^^^^^^^^^^^^^^^^^^^^^^^^^^^^^^^^^^
  File "C:\Users\LARRY\anaconda3\envs\tech-interview\Lib\socket.py", line 962, in getaddrinfo
    for res in _socket.getaddrinfo(host, port, family, type, proto, flags):
               ^^^^^^^^^^^^^^^^^^^^^^^^^^^^^^^^^^^^^^^^^^^^^^^^^^^^^^^^^^^
socket.gaierror: [Errno 11001] getaddrinfo failed

During handling of the above exception, another exception occurred:

Traceback (most recent call last):
  File "C:\Users\LARRY\anaconda3\envs\tech-interview\Lib\site-packages\dbt\cli\requires.py", line 178, in wrapper
    result, success = func(*args, **kwargs)
                      ^^^^^^^^^^^^^^^^^^^^^
  File "C:\Users\LARRY\anaconda3\envs\tech-interview\Lib\site-packages\dbt\cli\requires.py", line 128, in wrapper
    return func(*args, **kwargs)
           ^^^^^^^^^^^^^^^^^^^^^
  File "C:\Users\LARRY\anaconda3\envs\tech-interview\Lib\site-packages\dbt\cli\main.py", line 420, in debug
    results = task.run()
              ^^^^^^^^^^
  File "C:\Users\LARRY\anaconda3\envs\tech-interview\Lib\site-packages\dbt\task\debug.py", line 144, in run
    connection_status = self.test_connection()
                        ^^^^^^^^^^^^^^^^^^^^^^
  File "C:\Users\LARRY\anaconda3\envs\tech-interview\Lib\site-packages\dbt\task\debug.py", line 465, in test_connection
    connection_result = self.attempt_connection(self.profile)
                        ^^^^^^^^^^^^^^^^^^^^^^^^^^^^^^^^^^^^^
  File "C:\Users\LARRY\anaconda3\envs\tech-interview\Lib\site-packages\dbt\task\debug.py", line 443, in attempt_connection
    adapter.debug_query()
  File "C:\Users\LARRY\anaconda3\envs\tech-interview\Lib\site-packages\dbt\adapters\snowflake\impl.py", line 440, in debug_query
    self.execute("select 1 as id")
  File "C:\Users\LARRY\anaconda3\envs\tech-interview\Lib\site-packages\dbt_common\record.py", line 512, in record_replay_wrapper
    return func_to_record(*call_args, **kwargs)
           ^^^^^^^^^^^^^^^^^^^^^^^^^^^^^^^^^^^^
  File "C:\Users\LARRY\anaconda3\envs\tech-interview\Lib\site-packages\dbt\adapters\base\impl.py", line 450, in execute
    return self.connections.execute(sql=sql, auto_begin=auto_begin, fetch=fetch, limit=limit)
           ^^^^^^^^^^^^^^^^^^^^^^^^^^^^^^^^^^^^^^^^^^^^^^^^^^^^^^^^^^^^^^^^^^^^^^^^^^^^^^^^^^
  File "C:\Users\LARRY\anaconda3\envs\tech-interview\Lib\site-packages\dbt\adapters\snowflake\connections.py", line 520, in execute
    _, cursor = self.add_query(sql, auto_begin)
                ^^^^^^^^^^^^^^^^^^^^^^^^^^^^^^^
  File "C:\Users\LARRY\anaconda3\envs\tech-interview\Lib\site-packages\dbt\adapters\snowflake\connections.py", line 557, in add_query
    connection, cursor = self._add_standard_queries(
                         ^^^^^^^^^^^^^^^^^^^^^^^^^^^
  File "C:\Users\LARRY\anaconda3\envs\tech-interview\Lib\site-packages\dbt\adapters\snowflake\connections.py", line 616, in _add_standard_queries
    connection, cursor = self.add_standard_query(query, **kwargs)
                         ^^^^^^^^^^^^^^^^^^^^^^^^^^^^^^^^^^^^^^^^
  File "C:\Users\LARRY\anaconda3\envs\tech-interview\Lib\site-packages\dbt\adapters\snowflake\connections.py", line 531, in add_standard_query
    return super().add_query(self._add_query_comment(sql), **kwargs)
           ^^^^^^^^^^^^^^^^^^^^^^^^^^^^^^^^^^^^^^^^^^^^^^^^^^^^^^^^^
  File "C:\Users\LARRY\anaconda3\envs\tech-interview\Lib\site-packages\dbt\adapters\sql\connections.py", line 147, in add_query
    cursor = connection.handle.cursor()
             ^^^^^^^^^^^^^^^^^
  File "C:\Users\LARRY\anaconda3\envs\tech-interview\Lib\site-packages\dbt\adapters\contracts\connection.py", line 96, in handle
    self._handle.resolve(self)
  File "C:\Users\LARRY\anaconda3\envs\tech-interview\Lib\site-packages\dbt\adapters\contracts\connection.py", line 120, in resolve
    return self.opener(connection)
           ^^^^^^^^^^^^^^^^^^^^^^^
  File "C:\Users\LARRY\anaconda3\envs\tech-interview\Lib\site-packages\dbt\adapters\snowflake\connections.py", line 426, in open
    return cls.retry_connection(
           ^^^^^^^^^^^^^^^^^^^^^
  File "C:\Users\LARRY\anaconda3\envs\tech-interview\Lib\site-packages\dbt\adapters\base\connections.py", line 237, in retry_connection
    connection.handle = connect()
                        ^^^^^^^^^
  File "C:\Users\LARRY\anaconda3\envs\tech-interview\Lib\site-packages\dbt\adapters\snowflake\connections.py", line 386, in connect
    handle = snowflake.connector.connect(
             ^^^^^^^^^^^^^^^^^^^^^^^^^^^^
  File "C:\Users\LARRY\anaconda3\envs\tech-interview\Lib\site-packages\snowflake\connector\__init__.py", line 66, in Connect
    return SnowflakeConnection(**kwargs)
           ^^^^^^^^^^^^^^^^^^^^^^^^^^^^^
  File "C:\Users\LARRY\anaconda3\envs\tech-interview\Lib\site-packages\snowflake\connector\connection.py", line 588, in __init__
    self.connect(**kwargs)
  File "C:\Users\LARRY\anaconda3\envs\tech-interview\Lib\site-packages\snowflake\connector\connection.py", line 972, in connect
    self.__open_connection()
  File "C:\Users\LARRY\anaconda3\envs\tech-interview\Lib\site-packages\snowflake\connector\connection.py", line 1371, in __open_connection
    self.authenticate_with_retry(self.auth_class)
  File "C:\Users\LARRY\anaconda3\envs\tech-interview\Lib\site-packages\snowflake\connector\connection.py", line 1704, in authenticate_with_retry
    self._authenticate(auth_instance)
  File "C:\Users\LARRY\anaconda3\envs\tech-interview\Lib\site-packages\snowflake\connector\connection.py", line 1764, in _authenticate
    auth.authenticate(
  File "C:\Users\LARRY\anaconda3\envs\tech-interview\Lib\site-packages\snowflake\connector\auth\_auth.py", line 238, in authenticate
    ret = self._rest._post_request(
          ^^^^^^^^^^^^^^^^^^^^^^^^^
  File "C:\Users\LARRY\anaconda3\envs\tech-interview\Lib\site-packages\snowflake\connector\network.py", line 728, in _post_request
    ret = self.fetch(
          ^^^^^^^^^^^
  File "C:\Users\LARRY\anaconda3\envs\tech-interview\Lib\site-packages\snowflake\connector\network.py", line 847, in fetch
    ret = self._request_exec_wrapper(
          ^^^^^^^^^^^^^^^^^^^^^^^^^^^
  File "C:\Users\LARRY\anaconda3\envs\tech-interview\Lib\site-packages\snowflake\connector\network.py", line 898, in _request_exec_wrapper
    return_object = self._request_exec(
                    ^^^^^^^^^^^^^^^^^^^
  File "C:\Users\LARRY\anaconda3\envs\tech-interview\Lib\site-packages\snowflake\connector\network.py", line 1083, in _request_exec
    raw_ret = session.request(
              ^^^^^^^^^^^^^^^^
  File "C:\Users\LARRY\anaconda3\envs\tech-interview\Lib\site-packages\snowflake\connector\vendored\requests\sessions.py", line 589, in request
    resp = self.send(prep, **send_kwargs)
           ^^^^^^^^^^^^^^^^^^^^^^^^^^^^^^
  File "C:\Users\LARRY\anaconda3\envs\tech-interview\Lib\site-packages\snowflake\connector\vendored\requests\sessions.py", line 703, in send
    r = adapter.send(request, **kwargs)
        ^^^^^^^^^^^^^^^^^^^^^^^^^^^^^^^
  File "C:\Users\LARRY\anaconda3\envs\tech-interview\Lib\site-packages\snowflake\connector\vendored\requests\adapters.py", line 644, in send
    resp = conn.urlopen(
           ^^^^^^^^^^^^^
  File "C:\Users\LARRY\anaconda3\envs\tech-interview\Lib\site-packages\snowflake\connector\vendored\urllib3\connectionpool.py", line 787, in urlopen
    response = self._make_request(
               ^^^^^^^^^^^^^^^^^^^
  File "C:\Users\LARRY\anaconda3\envs\tech-interview\Lib\site-packages\snowflake\connector\vendored\urllib3\connectionpool.py", line 464, in _make_request
    self._validate_conn(conn)
  File "C:\Users\LARRY\anaconda3\envs\tech-interview\Lib\site-packages\snowflake\connector\vendored\urllib3\connectionpool.py", line 1093, in _validate_conn
    conn.connect()
  File "C:\Users\LARRY\anaconda3\envs\tech-interview\Lib\site-packages\snowflake\connector\vendored\urllib3\connection.py", line 762, in connect
    self.sock = sock = self._new_conn()
                       ^^^^^^^^^^^^^^^^
  File "C:\Users\LARRY\anaconda3\envs\tech-interview\Lib\site-packages\snowflake\connector\vendored\urllib3\connection.py", line 205, in _new_conn
    raise NameResolutionError(self.host, self, e) from e
                              ^^^^^^^^^
  File "C:\Users\LARRY\anaconda3\envs\tech-interview\Lib\site-packages\snowflake\connector\vendored\urllib3\connection.py", line 163, in host
    @property
    
KeyboardInterrupt

[0m20:03:40.010991 [debug] [MainThread]: Command `dbt debug` failed at 20:03:40.010991 after 34.55 seconds
[0m20:03:40.010991 [debug] [MainThread]: Connection 'debug' was properly closed.
[0m20:03:40.014262 [debug] [MainThread]: Sending event: {'category': 'dbt', 'action': 'invocation', 'label': 'end', 'context': [<snowplow_tracker.self_describing_json.SelfDescribingJson object at 0x000001B6D74D6BD0>, <snowplow_tracker.self_describing_json.SelfDescribingJson object at 0x000001B6D71FE650>, <snowplow_tracker.self_describing_json.SelfDescribingJson object at 0x000001B6D0327450>]}
[0m20:03:40.016420 [debug] [MainThread]: Flushing usage events
[0m20:03:42.169339 [debug] [MainThread]: An error was encountered while trying to flush usage events
